2018-10-30 17:44:05,390 [Thread-2:9120] [django.request:118] [exception:handle_uncaught_exception] [ERROR]- Internal Server Error: /app/
Traceback (most recent call last):
  File "C:\Users\Administrator\Envs\python1812-1\lib\site-packages\django\urls\base.py", line 75, in reverse
    extra, resolver = resolver.namespace_dict[ns]
KeyError: 'djdt'

During handling of the above exception, another exception occurred:

Traceback (most recent call last):
  File "C:\Users\Administrator\Envs\python1812-1\lib\site-packages\django\core\handlers\exception.py", line 35, in inner
    response = get_response(request)
  File "C:\Users\Administrator\Envs\python1812-1\lib\site-packages\django\utils\deprecation.py", line 97, in __call__
    response = self.process_response(request, response)
  File "C:\Users\Administrator\Envs\python1812-1\lib\site-packages\debug_toolbar\middleware.py", line 131, in process_response
    bits[-2] += toolbar.render_toolbar()
  File "C:\Users\Administrator\Envs\python1812-1\lib\site-packages\debug_toolbar\toolbar.py", line 65, in render_toolbar
    return render_to_string('debug_toolbar/base.html', context)
  File "C:\Users\Administrator\Envs\python1812-1\lib\site-packages\django\template\loader.py", line 62, in render_to_string
    return template.render(context, request)
  File "C:\Users\Administrator\Envs\python1812-1\lib\site-packages\django\template\backends\django.py", line 61, in render
    return self.template.render(context)
  File "C:\Users\Administrator\Envs\python1812-1\lib\site-packages\django\template\base.py", line 175, in render
    return self._render(context)
  File "C:\Users\Administrator\Envs\python1812-1\lib\site-packages\django\test\utils.py", line 98, in instrumented_test_render
    return self.nodelist.render(context)
  File "C:\Users\Administrator\Envs\python1812-1\lib\site-packages\django\template\base.py", line 943, in render
    bit = node.render_annotated(context)
  File "C:\Users\Administrator\Envs\python1812-1\lib\site-packages\django\template\base.py", line 910, in render_annotated
    return self.render(context)
  File "C:\Users\Administrator\Envs\python1812-1\lib\site-packages\django\template\defaulttags.py", line 314, in render
    return nodelist.render(context)
  File "C:\Users\Administrator\Envs\python1812-1\lib\site-packages\django\template\base.py", line 943, in render
    bit = node.render_annotated(context)
  File "C:\Users\Administrator\Envs\python1812-1\lib\site-packages\django\template\base.py", line 910, in render_annotated
    return self.render(context)
  File "C:\Users\Administrator\Envs\python1812-1\lib\site-packages\django\template\defaulttags.py", line 447, in render
    url = reverse(view_name, args=args, kwargs=kwargs, current_app=current_app)
  File "C:\Users\Administrator\Envs\python1812-1\lib\site-packages\django\urls\base.py", line 86, in reverse
    raise NoReverseMatch("%s is not a registered namespace" % key)
django.urls.exceptions.NoReverseMatch: 'djdt' is not a registered namespace
2018-10-31 09:09:05,589 [Thread-22:5668] [django.request:93] [base:get_response] [WARNING]- Not Found: /favicon.ico
2018-10-31 10:01:24,899 [Thread-10:432] [django.request:93] [base:get_response] [WARNING]- Not Found: /app/mine/{% url 'App:user_login' %}
2018-10-31 10:21:01,960 [Thread-6:6100] [django.request:118] [exception:handle_uncaught_exception] [ERROR]- Internal Server Error: /app/register/
Traceback (most recent call last):
  File "C:\Users\Administrator\Envs\python1812-1\lib\site-packages\django\core\handlers\exception.py", line 35, in inner
    response = get_response(request)
  File "C:\Users\Administrator\Envs\python1812-1\lib\site-packages\django\core\handlers\base.py", line 139, in _get_response
    "returned None instead." % (callback.__module__, view_name)
ValueError: The view App.views.user_register didn't return an HttpResponse object. It returned None instead.
2018-10-31 10:44:55,921 [Thread-63:5772] [django.request:118] [exception:handle_uncaught_exception] [ERROR]- Internal Server Error: /app/login/
Traceback (most recent call last):
  File "C:\Users\Administrator\Envs\python1812-1\lib\site-packages\django\core\handlers\exception.py", line 35, in inner
    response = get_response(request)
  File "C:\Users\Administrator\Envs\python1812-1\lib\site-packages\django\core\handlers\base.py", line 139, in _get_response
    "returned None instead." % (callback.__module__, view_name)
ValueError: The view App.views.user_login didn't return an HttpResponse object. It returned None instead.
2018-10-31 14:55:35,683 [Thread-6:1304] [django.request:118] [exception:handle_uncaught_exception] [ERROR]- Internal Server Error: /app/register/
Traceback (most recent call last):
  File "C:\Users\Administrator\Envs\python1812-1\lib\site-packages\django\core\handlers\exception.py", line 35, in inner
    response = get_response(request)
  File "C:\Users\Administrator\Envs\python1812-1\lib\site-packages\django\core\handlers\base.py", line 128, in _get_response
    response = self.process_exception_by_middleware(e, request)
  File "C:\Users\Administrator\Envs\python1812-1\lib\site-packages\django\core\handlers\base.py", line 126, in _get_response
    response = wrapped_callback(request, *callback_args, **callback_kwargs)
  File "C:\Users\Administrator\Desktop\mydjango\aixianfeng\App\views.py", line 152, in user_register
    send_mail('爱鲜蜂用户激活', '<a href="#">激活</a>', DEFAULT_FROM_EMAIL, [user.email, ])
  File "C:\Users\Administrator\Envs\python1812-1\lib\site-packages\django\core\mail\__init__.py", line 60, in send_mail
    return mail.send()
  File "C:\Users\Administrator\Envs\python1812-1\lib\site-packages\django\core\mail\message.py", line 294, in send
    return self.get_connection(fail_silently).send_messages([self])
  File "C:\Users\Administrator\Envs\python1812-1\lib\site-packages\django\core\mail\backends\smtp.py", line 103, in send_messages
    new_conn_created = self.open()
  File "C:\Users\Administrator\Envs\python1812-1\lib\site-packages\django\core\mail\backends\smtp.py", line 70, in open
    self.connection.login(self.username, self.password)
  File "c:\program files\python\Lib\smtplib.py", line 730, in login
    raise last_exception
  File "c:\program files\python\Lib\smtplib.py", line 721, in login
    initial_response_ok=initial_response_ok)
  File "c:\program files\python\Lib\smtplib.py", line 642, in auth
    raise SMTPAuthenticationError(code, resp)
smtplib.SMTPAuthenticationError: (535, b'Error: authentication failed')
2018-10-31 14:59:58,458 [Thread-14:8932] [django.request:118] [exception:handle_uncaught_exception] [ERROR]- Internal Server Error: /app/register/
Traceback (most recent call last):
  File "C:\Users\Administrator\Envs\python1812-1\lib\site-packages\django\db\backends\utils.py", line 85, in _execute
    return self.cursor.execute(sql, params)
  File "C:\Users\Administrator\Envs\python1812-1\lib\site-packages\django\db\backends\mysql\base.py", line 71, in execute
    return self.cursor.execute(query, args)
  File "C:\Users\Administrator\Envs\python1812-1\lib\site-packages\MySQLdb\cursors.py", line 250, in execute
    self.errorhandler(self, exc, value)
  File "C:\Users\Administrator\Envs\python1812-1\lib\site-packages\MySQLdb\connections.py", line 50, in defaulterrorhandler
    raise errorvalue
  File "C:\Users\Administrator\Envs\python1812-1\lib\site-packages\MySQLdb\cursors.py", line 247, in execute
    res = self._query(query)
  File "C:\Users\Administrator\Envs\python1812-1\lib\site-packages\MySQLdb\cursors.py", line 412, in _query
    rowcount = self._do_query(q)
  File "C:\Users\Administrator\Envs\python1812-1\lib\site-packages\MySQLdb\cursors.py", line 375, in _do_query
    db.query(q)
  File "C:\Users\Administrator\Envs\python1812-1\lib\site-packages\MySQLdb\connections.py", line 276, in query
    _mysql.connection.query(self, query)
_mysql_exceptions.IntegrityError: (1062, "Duplicate entry 'studenttest@163.com' for key 'email'")

The above exception was the direct cause of the following exception:

Traceback (most recent call last):
  File "C:\Users\Administrator\Envs\python1812-1\lib\site-packages\django\core\handlers\exception.py", line 35, in inner
    response = get_response(request)
  File "C:\Users\Administrator\Envs\python1812-1\lib\site-packages\django\core\handlers\base.py", line 128, in _get_response
    response = self.process_exception_by_middleware(e, request)
  File "C:\Users\Administrator\Envs\python1812-1\lib\site-packages\django\core\handlers\base.py", line 126, in _get_response
    response = wrapped_callback(request, *callback_args, **callback_kwargs)
  File "C:\Users\Administrator\Desktop\mydjango\aixianfeng\App\views.py", line 149, in user_register
    user.save()
  File "C:\Users\Administrator\Envs\python1812-1\lib\site-packages\django\db\models\base.py", line 729, in save
    force_update=force_update, update_fields=update_fields)
  File "C:\Users\Administrator\Envs\python1812-1\lib\site-packages\django\db\models\base.py", line 759, in save_base
    updated = self._save_table(raw, cls, force_insert, force_update, using, update_fields)
  File "C:\Users\Administrator\Envs\python1812-1\lib\site-packages\django\db\models\base.py", line 842, in _save_table
    result = self._do_insert(cls._base_manager, using, fields, update_pk, raw)
  File "C:\Users\Administrator\Envs\python1812-1\lib\site-packages\django\db\models\base.py", line 880, in _do_insert
    using=using, raw=raw)
  File "C:\Users\Administrator\Envs\python1812-1\lib\site-packages\django\db\models\manager.py", line 82, in manager_method
    return getattr(self.get_queryset(), name)(*args, **kwargs)
  File "C:\Users\Administrator\Envs\python1812-1\lib\site-packages\django\db\models\query.py", line 1125, in _insert
    return query.get_compiler(using=using).execute_sql(return_id)
  File "C:\Users\Administrator\Envs\python1812-1\lib\site-packages\django\db\models\sql\compiler.py", line 1285, in execute_sql
    cursor.execute(sql, params)
  File "C:\Users\Administrator\Envs\python1812-1\lib\site-packages\debug_toolbar\panels\sql\tracking.py", line 176, in execute
    return self._record(self.cursor.execute, sql, params)
  File "C:\Users\Administrator\Envs\python1812-1\lib\site-packages\debug_toolbar\panels\sql\tracking.py", line 117, in _record
    return method(sql, params)
  File "C:\Users\Administrator\Envs\python1812-1\lib\site-packages\django\db\backends\utils.py", line 100, in execute
    return super().execute(sql, params)
  File "C:\Users\Administrator\Envs\python1812-1\lib\site-packages\django\db\backends\utils.py", line 68, in execute
    return self._execute_with_wrappers(sql, params, many=False, executor=self._execute)
  File "C:\Users\Administrator\Envs\python1812-1\lib\site-packages\django\db\backends\utils.py", line 77, in _execute_with_wrappers
    return executor(sql, params, many, context)
  File "C:\Users\Administrator\Envs\python1812-1\lib\site-packages\django\db\backends\utils.py", line 85, in _execute
    return self.cursor.execute(sql, params)
  File "C:\Users\Administrator\Envs\python1812-1\lib\site-packages\django\db\utils.py", line 89, in __exit__
    raise dj_exc_value.with_traceback(traceback) from exc_value
  File "C:\Users\Administrator\Envs\python1812-1\lib\site-packages\django\db\backends\utils.py", line 85, in _execute
    return self.cursor.execute(sql, params)
  File "C:\Users\Administrator\Envs\python1812-1\lib\site-packages\django\db\backends\mysql\base.py", line 71, in execute
    return self.cursor.execute(query, args)
  File "C:\Users\Administrator\Envs\python1812-1\lib\site-packages\MySQLdb\cursors.py", line 250, in execute
    self.errorhandler(self, exc, value)
  File "C:\Users\Administrator\Envs\python1812-1\lib\site-packages\MySQLdb\connections.py", line 50, in defaulterrorhandler
    raise errorvalue
  File "C:\Users\Administrator\Envs\python1812-1\lib\site-packages\MySQLdb\cursors.py", line 247, in execute
    res = self._query(query)
  File "C:\Users\Administrator\Envs\python1812-1\lib\site-packages\MySQLdb\cursors.py", line 412, in _query
    rowcount = self._do_query(q)
  File "C:\Users\Administrator\Envs\python1812-1\lib\site-packages\MySQLdb\cursors.py", line 375, in _do_query
    db.query(q)
  File "C:\Users\Administrator\Envs\python1812-1\lib\site-packages\MySQLdb\connections.py", line 276, in query
    _mysql.connection.query(self, query)
django.db.utils.IntegrityError: (1062, "Duplicate entry 'studenttest@163.com' for key 'email'")
2018-10-31 16:47:36,742 [Thread-5:10056] [django.request:93] [base:get_response] [WARNING]- Not Found: /app/mine/uploads/2018/10/31/ad300x100.jpg
2018-10-31 17:15:29,506 [Thread-15:9996] [django.request:93] [base:get_response] [WARNING]- Not Found: /app/mine/uploads/2018/10/31/ad300x100.jpg
2018-10-31 17:15:38,856 [Thread-18:2660] [django.request:93] [base:get_response] [WARNING]- Not Found: /app/mine/uploads/2018/10/31/ad300x100.jpg
2018-11-01 09:10:03,765 [Thread-3:3892] [django.request:93] [base:get_response] [WARNING]- Not Found: /favicon.ico
2018-11-01 09:26:07,538 [Thread-7:4740] [django.request:118] [exception:handle_uncaught_exception] [ERROR]- Internal Server Error: /app/mine/
Traceback (most recent call last):
  File "C:\Users\Administrator\Envs\python1812-1\lib\site-packages\django\core\handlers\exception.py", line 35, in inner
    response = get_response(request)
  File "C:\Users\Administrator\Envs\python1812-1\lib\site-packages\django\core\handlers\base.py", line 128, in _get_response
    response = self.process_exception_by_middleware(e, request)
  File "C:\Users\Administrator\Envs\python1812-1\lib\site-packages\django\core\handlers\base.py", line 126, in _get_response
    response = wrapped_callback(request, *callback_args, **callback_kwargs)
  File "C:\Users\Administrator\Desktop\mydjango\aixianfeng\App\views.py", line 102, in show_mine
    username = request.session['username']
  File "C:\Users\Administrator\Envs\python1812-1\lib\site-packages\django\contrib\sessions\backends\base.py", line 55, in __getitem__
    return self._session[key]
KeyError: 'username'
2018-11-01 09:44:29,892 [Thread-30:2052] [django.request:93] [base:get_response] [WARNING]- Not Found: /favicon.ico
2018-11-01 09:46:45,133 [Thread-65:4524] [django.request:93] [base:get_response] [WARNING]- Not Found: /favicon.ico
2018-11-01 10:42:47,752 [Thread-23:6280] [django.request:93] [base:get_response] [WARNING]- Not Found: /favicon.ico
2018-11-01 10:44:51,892 [Thread-53:2616] [django.request:93] [base:get_response] [WARNING]- Not Found: /favicon.ico
2018-11-01 11:21:33,995 [Thread-23:1532] [django.request:93] [base:get_response] [WARNING]- Not Found: /favicon.ico
2018-11-01 11:27:43,806 [Thread-42:5988] [django.request:93] [base:get_response] [WARNING]- Not Found: /favicon.ico
2018-11-01 11:28:14,305 [Thread-74:356] [django.request:93] [base:get_response] [WARNING]- Not Found: /favicon.ico
2018-11-01 11:29:00,901 [Thread-88:6308] [django.request:118] [exception:handle_uncaught_exception] [ERROR]- Internal Server Error: /app/addCart/
Traceback (most recent call last):
  File "C:\Users\Administrator\Envs\python1812-1\lib\site-packages\django\core\handlers\exception.py", line 35, in inner
    response = get_response(request)
  File "C:\Users\Administrator\Envs\python1812-1\lib\site-packages\django\utils\deprecation.py", line 93, in __call__
    response = self.process_request(request)
  File "C:\Users\Administrator\Desktop\mydjango\aixianfeng\middleware\mymiddleware.py", line 27, in process_request
    if user.exists():
AttributeError: 'AXFUser' object has no attribute 'exists'
2018-11-01 11:29:04,629 [Thread-89:6740] [django.request:118] [exception:handle_uncaught_exception] [ERROR]- Internal Server Error: /app/addCart/
Traceback (most recent call last):
  File "C:\Users\Administrator\Envs\python1812-1\lib\site-packages\django\core\handlers\exception.py", line 35, in inner
    response = get_response(request)
  File "C:\Users\Administrator\Envs\python1812-1\lib\site-packages\django\utils\deprecation.py", line 93, in __call__
    response = self.process_request(request)
  File "C:\Users\Administrator\Desktop\mydjango\aixianfeng\middleware\mymiddleware.py", line 27, in process_request
    if user.exists():
AttributeError: 'AXFUser' object has no attribute 'exists'
2018-11-01 11:29:08,404 [Thread-90:5488] [django.request:118] [exception:handle_uncaught_exception] [ERROR]- Internal Server Error: /app/addCart/
Traceback (most recent call last):
  File "C:\Users\Administrator\Envs\python1812-1\lib\site-packages\django\core\handlers\exception.py", line 35, in inner
    response = get_response(request)
  File "C:\Users\Administrator\Envs\python1812-1\lib\site-packages\django\utils\deprecation.py", line 93, in __call__
    response = self.process_request(request)
  File "C:\Users\Administrator\Desktop\mydjango\aixianfeng\middleware\mymiddleware.py", line 27, in process_request
    if user.exists():
AttributeError: 'AXFUser' object has no attribute 'exists'
2018-11-01 11:29:09,000 [Thread-91:6400] [django.request:118] [exception:handle_uncaught_exception] [ERROR]- Internal Server Error: /app/addCart/
Traceback (most recent call last):
  File "C:\Users\Administrator\Envs\python1812-1\lib\site-packages\django\core\handlers\exception.py", line 35, in inner
    response = get_response(request)
  File "C:\Users\Administrator\Envs\python1812-1\lib\site-packages\django\utils\deprecation.py", line 93, in __call__
    response = self.process_request(request)
  File "C:\Users\Administrator\Desktop\mydjango\aixianfeng\middleware\mymiddleware.py", line 27, in process_request
    if user.exists():
AttributeError: 'AXFUser' object has no attribute 'exists'
2018-11-01 11:53:09,112 [Thread-23:3328] [django.request:93] [base:get_response] [WARNING]- Not Found: /favicon.ico
2018-11-01 11:53:36,756 [Thread-48:5344] [django.request:93] [base:get_response] [WARNING]- Not Found: /favicon.ico
2018-11-01 11:54:00,992 [Thread-51:6668] [django.request:93] [base:get_response] [WARNING]- Not Found: /favicon.ico
2018-11-01 11:54:33,066 [Thread-55:6136] [django.request:118] [exception:handle_uncaught_exception] [ERROR]- Internal Server Error: /app/addCart/
Traceback (most recent call last):
  File "C:\Users\Administrator\Envs\python1812-1\lib\site-packages\django\core\handlers\exception.py", line 35, in inner
    response = get_response(request)
  File "C:\Users\Administrator\Envs\python1812-1\lib\site-packages\django\core\handlers\base.py", line 128, in _get_response
    response = self.process_exception_by_middleware(e, request)
  File "C:\Users\Administrator\Envs\python1812-1\lib\site-packages\django\core\handlers\base.py", line 126, in _get_response
    response = wrapped_callback(request, *callback_args, **callback_kwargs)
  File "C:\Users\Administrator\Desktop\mydjango\aixianfeng\App\views.py", line 233, in add_cart
    cart.user = request.user
  File "C:\Users\Administrator\Envs\python1812-1\lib\site-packages\django\db\models\fields\related_descriptors.py", line 280, in __set__
    super().__set__(instance, value)
  File "C:\Users\Administrator\Envs\python1812-1\lib\site-packages\django\db\models\fields\related_descriptors.py", line 197, in __set__
    self.field.remote_field.model._meta.object_name,
ValueError: Cannot assign "<QuerySet [<AXFUser: admin123>]>": "Cart.user" must be a "AXFUser" instance.
2018-11-01 11:55:51,011 [Thread-2:4220] [django.request:118] [exception:handle_uncaught_exception] [ERROR]- Internal Server Error: /app/addCart/
Traceback (most recent call last):
  File "C:\Users\Administrator\Envs\python1812-1\lib\site-packages\django\core\handlers\exception.py", line 35, in inner
    response = get_response(request)
  File "C:\Users\Administrator\Envs\python1812-1\lib\site-packages\django\core\handlers\base.py", line 128, in _get_response
    response = self.process_exception_by_middleware(e, request)
  File "C:\Users\Administrator\Envs\python1812-1\lib\site-packages\django\core\handlers\base.py", line 126, in _get_response
    response = wrapped_callback(request, *callback_args, **callback_kwargs)
  File "C:\Users\Administrator\Desktop\mydjango\aixianfeng\App\views.py", line 234, in add_cart
    cart.user = request.user
  File "C:\Users\Administrator\Envs\python1812-1\lib\site-packages\django\db\models\fields\related_descriptors.py", line 280, in __set__
    super().__set__(instance, value)
  File "C:\Users\Administrator\Envs\python1812-1\lib\site-packages\django\db\models\fields\related_descriptors.py", line 197, in __set__
    self.field.remote_field.model._meta.object_name,
ValueError: Cannot assign "<QuerySet [<AXFUser: admin123>]>": "Cart.user" must be a "AXFUser" instance.
2018-11-01 11:56:44,855 [Thread-7:5524] [django.request:118] [exception:handle_uncaught_exception] [ERROR]- Internal Server Error: /app/addCart/
Traceback (most recent call last):
  File "C:\Users\Administrator\Envs\python1812-1\lib\site-packages\django\core\handlers\exception.py", line 35, in inner
    response = get_response(request)
  File "C:\Users\Administrator\Envs\python1812-1\lib\site-packages\django\core\handlers\base.py", line 128, in _get_response
    response = self.process_exception_by_middleware(e, request)
  File "C:\Users\Administrator\Envs\python1812-1\lib\site-packages\django\core\handlers\base.py", line 126, in _get_response
    response = wrapped_callback(request, *callback_args, **callback_kwargs)
  File "C:\Users\Administrator\Desktop\mydjango\aixianfeng\App\views.py", line 234, in add_cart
    cart.user = request.user
  File "C:\Users\Administrator\Envs\python1812-1\lib\site-packages\django\db\models\fields\related_descriptors.py", line 280, in __set__
    super().__set__(instance, value)
  File "C:\Users\Administrator\Envs\python1812-1\lib\site-packages\django\db\models\fields\related_descriptors.py", line 197, in __set__
    self.field.remote_field.model._meta.object_name,
ValueError: Cannot assign "<QuerySet [<AXFUser: admin123>]>": "Cart.user" must be a "AXFUser" instance.
2018-11-01 11:57:43,443 [Thread-23:6888] [django.request:93] [base:get_response] [WARNING]- Not Found: /favicon.ico
